<?xml version="1.0" encoding="utf-8"?>
<!-- This URDF was automatically created by SolidWorks to URDF Exporter! Originally created by Stephen Brawner (brawner@gmail.com) 
     Commit Version: 1.5.1-0-g916b5db  Build Version: 1.5.7152.31018
     For more information, please see http://wiki.ros.org/sw_urdf_exporter -->
<robot
  name="rocr6_description">
  <link
    name="base_link">
    <inertial>
      <origin
        xyz="5.2457E-05 0.00029238 0.032631"
        rpy="0 0 0" />
      <mass
        value="0.55222" />
      <inertia
        ixx="0.00088318"
        ixy="8.5071E-08"
        ixz="-2.1528E-07"
        iyy="0.00091817"
        iyz="-9.8095E-06"
        izz="0.0012568" />
    </inertial>
    <visual>
      <origin
        xyz="0 0 0"
        rpy="0 0 0" />
      <geometry>
        <mesh
          filename="package://rocr6_description/meshes/base_link.STL" />
      </geometry>
      <material
        name="">
        <color
          rgba="0.79216 0.81961 0.93333 1" />
      </material>
    </visual>
    <collision>
      <origin
        xyz="0 0 0"
        rpy="0 0 0" />
      <geometry>
        <mesh
          filename="package://rocr6_description/meshes/base_link.STL" />
      </geometry>
    </collision>
  </link>
  <link
    name="link1">
    <inertial>
      <origin
        xyz="-5.6107E-06 -0.0096745 0.055302"
        rpy="0 0 0" />
      <mass
        value="0.39053" />
      <inertia
        ixx="0.00057949"
        ixy="8.1622E-08"
        ixz="1.1435E-08"
        iyy="0.00057332"
        iyz="3.7498E-05"
        izz="0.000767" />
    </inertial>
    <visual>
      <origin
        xyz="0 0 0"
        rpy="0 0 0" />
      <geometry>
        <mesh
          filename="package://rocr6_description/meshes/link1.STL" />
      </geometry>
      <material
        name="">
        <color
          rgba="0.79216 0.81961 0.93333 1" />
      </material>
    </visual>
    <collision>
      <origin
        xyz="0 0 0"
        rpy="0 0 0" />
      <geometry>
        <mesh
          filename="package://rocr6_description/meshes/link1.STL" />
      </geometry>
    </collision>
  </link>
  <joint
    name="joint1"
    type="revolute">
    <origin
      xyz="6.6537E-05 0.00042955 0.08205"
      rpy="0 0 0" />
    <parent
      link="base_link" />
    <child
      link="link1" />
    <axis
      xyz="0 0 1" />
    <limit
      lower="-3.14"
      upper="3.14"
      effort="150"
      velocity="3.2" />
  </joint>
  <link
    name="link2">
    <inertial>
      <origin
        xyz="1.7326E-13 -0.057367 0.13201"
        rpy="0 0 0" />
      <mass
        value="1.0634" />
      <inertia
        ixx="0.0021253"
        ixy="3.6446E-13"
        ixz="1.6324E-07"
        iyy="0.0025003"
        iyz="5.4629E-15"
        izz="0.0016353" />
    </inertial>
    <visual>
      <origin
        xyz="0 0 0"
        rpy="0 0 0" />
      <geometry>
        <mesh
          filename="package://rocr6_description/meshes/link2.STL" />
      </geometry>
      <material
        name="">
        <color
          rgba="0.79216 0.81961 0.93333 1" />
      </material>
    </visual>
    <collision>
      <origin
        xyz="0 0 0"
        rpy="0 0 0" />
      <geometry>
        <mesh
          filename="package://rocr6_description/meshes/link2.STL" />
      </geometry>
    </collision>
  </link>
  <joint
    name="joint2"
    type="revolute">
    <origin
      xyz="0 -0.05775 0.06195"
      rpy="0 0 0" />
    <parent
      link="link1" />
    <child
      link="link2" />
    <axis
      xyz="0 -1 0" />
    <limit
      lower="-3.14"
      upper="3.14"
      effort="150"
      velocity="3.2" />
  </joint>
  <link
    name="link3">
    <inertial>
      <origin
        xyz="2.8296E-07 0.10648 -0.055036"
        rpy="0 0 0" />
      <mass
        value="0.60237" />
      <inertia
        ixx="0.0010998"
        ixy="-9.029E-09"
        ixz="5.4949E-09"
        iyy="0.00083242"
        iyz="5.0826E-05"
        izz="0.0011403" />
    </inertial>
    <visual>
      <origin
        xyz="0 0 0"
        rpy="0 0 0" />
      <geometry>
        <mesh
          filename="package://rocr6_description/meshes/link3.STL" />
      </geometry>
      <material
        name="">
        <color
          rgba="0.79216 0.81961 0.93333 1" />
      </material>
    </visual>
    <collision>
      <origin
        xyz="0 0 0"
        rpy="0 0 0" />
      <geometry>
        <mesh
          filename="package://rocr6_description/meshes/link3.STL" />
      </geometry>
    </collision>
  </link>
  <joint
    name="joint3"
    type="revolute">
    <origin
      xyz="0 -0.00043165 0.264"
      rpy="1.5708 0 0" />
    <parent
      link="link2" />
    <child
      link="link3" />
    <axis
      xyz="0 0 1" />
    <limit
      lower="-3.14"
      upper="3.14"
      effort="150"
      velocity="3.2" />
  </joint>
  <link
    name="link4">
    <inertial>
      <origin
        xyz="2.8519E-07 -0.052441 0.0067616"
        rpy="0 0 0" />
      <mass
        value="0.17474" />
      <inertia
        ixx="0.0002242"
        ixy="5.9814E-11"
        ixz="1.8015E-09"
        iyy="0.00021561"
        iyz="3.3297E-05"
        izz="0.00027423" />
    </inertial>
    <visual>
      <origin
        xyz="0 0 0"
        rpy="0 0 0" />
      <geometry>
        <mesh
          filename="package://rocr6_description/meshes/link4.STL" />
      </geometry>
      <material
        name="">
        <color
          rgba="0.79216 0.81961 0.93333 1" />
      </material>
    </visual>
    <collision>
      <origin
        xyz="0 0 0"
        rpy="0 0 0" />
      <geometry>
        <mesh
          filename="package://rocr6_description/meshes/link4.STL" />
      </geometry>
    </collision>
  </link>
  <joint
    name="joint4"
    type="revolute">
    <origin
      xyz="0 0.237 -0.015882"
      rpy="-1.5708 0 0" />
    <parent
      link="link3" />
    <child
      link="link4" />
    <axis
      xyz="0 1 0" />
    <limit
      lower="-3.14"
      upper="3.14"
      effort="80"
      velocity="1.5" />
  </joint>
  <link
    name="link5">
    <inertial>
      <origin
        xyz="-2.8519E-07 -0.0067616 0.052441"
        rpy="0 0 0" />
      <mass
        value="0.17474" />
      <inertia
        ixx="0.0002242"
        ixy="1.8015E-09"
        ixz="5.9814E-11"
        iyy="0.00027423"
        iyz="3.3297E-05"
        izz="0.00021561" />
    </inertial>
    <visual>
      <origin
        xyz="0 0 0"
        rpy="0 0 0" />
      <geometry>
        <mesh
          filename="package://rocr6_description/meshes/link5.STL" />
      </geometry>
      <material
        name="">
        <color
          rgba="0.79216 0.81961 0.93333 1" />
      </material>
    </visual>
    <collision>
      <origin
        xyz="0 0 0"
        rpy="0 0 0" />
      <geometry>
        <mesh
          filename="package://rocr6_description/meshes/link5.STL" />
      </geometry>
    </collision>
  </link>
  <joint
    name="joint5"
    type="revolute">
    <origin
      xyz="0 -0.0642 0.0498"
      rpy="0 0 0" />
    <parent
      link="link4" />
    <child
      link="link5" />
    <axis
      xyz="0 0 -1" />
    <limit
      lower="-3.14"
      upper="3.14"
      effort="80"
      velocity="1.5" />
  </joint>
  <link
    name="link6">
    <inertial>
      <origin
        xyz="-0.00040806 -0.026005 2.3021E-05"
        rpy="0 0 0" />
      <mass
        value="0.17591" />
      <inertia
        ixx="9.4853E-05"
        ixy="1.8268E-07"
        ixz="-1.6342E-09"
        iyy="0.00015924"
        iyz="4.5335E-08"
        izz="9.2958E-05" />
    </inertial>
    <visual>
      <origin
        xyz="0 0 0"
        rpy="0 0 0" />
      <geometry>
        <mesh
          filename="package://rocr6_description/meshes/link6.STL" />
      </geometry>
      <material
        name="">
        <color
          rgba="0.86667 0.86667 0.8902 1" />
      </material>
    </visual>
    <collision>
      <origin
        xyz="0 0 0"
        rpy="0 0 0" />
      <geometry>
        <mesh
          filename="package://rocr6_description/meshes/link6.STL" />
      </geometry>
    </collision>
  </link>
  <joint
    name="joint6"
    type="revolute">
    <origin
      xyz="0 -0.0498 0.0642"
      rpy="0 0 0" />
    <parent
      link="link5" />
    <child
      link="link6" />
    <axis
      xyz="0 1 0" />
    <limit
      lower="-3.14"
      upper="3.14"
      effort="80"
      velocity="1.5" />
  </joint>
</robot>